2025-03-15 11:49:38,153 - src.services.ollama_service - INFO - OllamaClient initialized
2025-03-15 11:50:12,605 - src.services.ollama_service - INFO - OllamaClient initialized
2025-03-15 11:53:04,403 - src.services.ollama_service - INFO - OllamaClient initialized
2025-03-15 11:53:05,302 - src.services.ollama_service - INFO - OllamaClient initialized
2025-03-15 11:55:14,773 - src.services.ollama_service - INFO - Generating manzai script for topic: カレーメシ
2025-03-15 11:55:14,776 - src.services.ollama_service - ERROR - API request failed
Traceback (most recent call last):
  File "/home/persona/analysis/ManzAI_Studio/src/services/ollama_service.py", line 181, in generate_json_sync
    response.raise_for_status()
  File "/home/persona/analysis/ManzAI_Studio/.venv/lib/python3.10/site-packages/requests/models.py", line 1024, in raise_for_status
    raise HTTPError(http_error_msg, response=self)
requests.exceptions.HTTPError: 404 Client Error: Not Found for url: http://localhost:11434/api/generate
2025-03-15 11:55:14,793 - src.services.ollama_service - WARNING - Failed to generate JSON response, falling back to text: Connection error: 404 Client Error: Not Found for url: http://localhost:11434/api/generate
2025-03-15 11:55:14,796 - src.services.ollama_service - ERROR - API request failed
Traceback (most recent call last):
  File "/home/persona/analysis/ManzAI_Studio/src/services/ollama_service.py", line 141, in generate_text_sync
    response.raise_for_status()
  File "/home/persona/analysis/ManzAI_Studio/.venv/lib/python3.10/site-packages/requests/models.py", line 1024, in raise_for_status
    raise HTTPError(http_error_msg, response=self)
requests.exceptions.HTTPError: 404 Client Error: Not Found for url: http://localhost:11434/api/generate
2025-03-15 11:55:14,798 - src.services.ollama_service - ERROR - Failed to generate manzai script: Connection error: 404 Client Error: Not Found for url: http://localhost:11434/api/generate
2025-03-15 11:55:35,538 - src.services.ollama_service - INFO - OllamaClient initialized
2025-03-15 11:56:15,287 - src.services.ollama_service - INFO - OllamaClient initialized
2025-03-15 11:56:15,488 - src.services.ollama_service - INFO - OllamaClient initialized
2025-03-15 11:56:26,737 - src.services.ollama_service - INFO - Generating manzai script for topic: カレーメシ
2025-03-15 11:56:26,740 - src.services.ollama_service - ERROR - API request failed
Traceback (most recent call last):
  File "/home/persona/analysis/ManzAI_Studio/src/services/ollama_service.py", line 184, in generate_json_sync
    response.raise_for_status()
  File "/home/persona/.pyenv/versions/3.10.13/lib/python3.10/site-packages/requests/models.py", line 1024, in raise_for_status
    raise HTTPError(http_error_msg, response=self)
requests.exceptions.HTTPError: 404 Client Error: Not Found for url: http://localhost:11434/api/generate
2025-03-15 11:56:26,743 - src.services.ollama_service - WARNING - Failed to generate JSON response, falling back to text: Connection error: 404 Client Error: Not Found for url: http://localhost:11434/api/generate
2025-03-15 11:56:26,745 - src.services.ollama_service - ERROR - API request failed
Traceback (most recent call last):
  File "/home/persona/analysis/ManzAI_Studio/src/services/ollama_service.py", line 144, in generate_text_sync
    response.raise_for_status()
  File "/home/persona/.pyenv/versions/3.10.13/lib/python3.10/site-packages/requests/models.py", line 1024, in raise_for_status
    raise HTTPError(http_error_msg, response=self)
requests.exceptions.HTTPError: 404 Client Error: Not Found for url: http://localhost:11434/api/generate
2025-03-15 11:56:26,745 - src.services.ollama_service - ERROR - Failed to generate manzai script: Connection error: 404 Client Error: Not Found for url: http://localhost:11434/api/generate
2025-03-15 11:56:49,540 - src.services.ollama_service - INFO - Generating manzai script for topic: カレーメシ
2025-03-15 11:56:49,542 - src.services.ollama_service - ERROR - API request failed
Traceback (most recent call last):
  File "/home/persona/analysis/ManzAI_Studio/src/services/ollama_service.py", line 184, in generate_json_sync
    response.raise_for_status()
  File "/home/persona/.pyenv/versions/3.10.13/lib/python3.10/site-packages/requests/models.py", line 1024, in raise_for_status
    raise HTTPError(http_error_msg, response=self)
requests.exceptions.HTTPError: 404 Client Error: Not Found for url: http://localhost:11434/api/generate
2025-03-15 11:56:49,543 - src.services.ollama_service - WARNING - Failed to generate JSON response, falling back to text: Connection error: 404 Client Error: Not Found for url: http://localhost:11434/api/generate
2025-03-15 11:56:49,545 - src.services.ollama_service - ERROR - API request failed
Traceback (most recent call last):
  File "/home/persona/analysis/ManzAI_Studio/src/services/ollama_service.py", line 144, in generate_text_sync
    response.raise_for_status()
  File "/home/persona/.pyenv/versions/3.10.13/lib/python3.10/site-packages/requests/models.py", line 1024, in raise_for_status
    raise HTTPError(http_error_msg, response=self)
requests.exceptions.HTTPError: 404 Client Error: Not Found for url: http://localhost:11434/api/generate
2025-03-15 11:56:49,546 - src.services.ollama_service - ERROR - Failed to generate manzai script: Connection error: 404 Client Error: Not Found for url: http://localhost:11434/api/generate
2025-03-15 11:58:01,363 - src.services.ollama_service - INFO - OllamaClient initialized
2025-03-15 11:58:03,591 - src.services.ollama_service - INFO - OllamaClient initialized
2025-03-15 11:58:20,268 - src.services.ollama_service - INFO - OllamaClient initialized
2025-03-15 11:58:20,533 - src.services.ollama_service - INFO - OllamaClient initialized
2025-03-15 11:58:28,100 - src.services.ollama_service - INFO - Generating manzai script for topic: カレーメシ
2025-03-15 11:58:28,110 - src.services.ollama_service - ERROR - API request failed
Traceback (most recent call last):
  File "/home/persona/analysis/ManzAI_Studio/src/services/ollama_service.py", line 144, in generate_text_sync
    response.raise_for_status()
  File "/home/persona/.pyenv/versions/3.10.13/lib/python3.10/site-packages/requests/models.py", line 1024, in raise_for_status
    raise HTTPError(http_error_msg, response=self)
requests.exceptions.HTTPError: 404 Client Error: Not Found for url: http://localhost:11434/api/generate
2025-03-15 11:58:28,112 - src.services.ollama_service - WARNING - Failed to generate JSON response, falling back to text: Connection error: 404 Client Error: Not Found for url: http://localhost:11434/api/generate
2025-03-15 11:58:28,114 - src.services.ollama_service - ERROR - API request failed
Traceback (most recent call last):
  File "/home/persona/analysis/ManzAI_Studio/src/services/ollama_service.py", line 144, in generate_text_sync
    response.raise_for_status()
  File "/home/persona/.pyenv/versions/3.10.13/lib/python3.10/site-packages/requests/models.py", line 1024, in raise_for_status
    raise HTTPError(http_error_msg, response=self)
requests.exceptions.HTTPError: 404 Client Error: Not Found for url: http://localhost:11434/api/generate

During handling of the above exception, another exception occurred:

Traceback (most recent call last):
  File "/home/persona/analysis/ManzAI_Studio/src/services/ollama_service.py", line 242, in generate_manzai_script
    generated_text = self.generate_text_sync(prompt, additional_options)
  File "/home/persona/analysis/ManzAI_Studio/src/services/ollama_service.py", line 156, in generate_text_sync
    self._handle_api_error(e)
  File "/home/persona/analysis/ManzAI_Studio/src/services/ollama_service.py", line 113, in _handle_api_error
    raise OllamaServiceError(f"Connection error: {str(error)}")
src.services.ollama_service.OllamaServiceError: Connection error: 404 Client Error: Not Found for url: http://localhost:11434/api/generate

During handling of the above exception, another exception occurred:

Traceback (most recent call last):
  File "/home/persona/analysis/ManzAI_Studio/src/services/ollama_service.py", line 144, in generate_text_sync
    response.raise_for_status()
  File "/home/persona/.pyenv/versions/3.10.13/lib/python3.10/site-packages/requests/models.py", line 1024, in raise_for_status
    raise HTTPError(http_error_msg, response=self)
requests.exceptions.HTTPError: 404 Client Error: Not Found for url: http://localhost:11434/api/generate
2025-03-15 11:58:28,116 - src.services.ollama_service - ERROR - Failed to generate manzai script: Connection error: 404 Client Error: Not Found for url: http://localhost:11434/api/generate
2025-03-15 11:59:19,092 - src.services.ollama_service - INFO - OllamaClient initialized
2025-03-15 11:59:20,640 - src.services.ollama_service - INFO - OllamaClient initialized
2025-03-15 11:59:57,598 - src.services.ollama_service - INFO - OllamaClient initialized
2025-03-15 11:59:58,979 - src.services.ollama_service - INFO - OllamaClient initialized
2025-03-15 12:00:14,649 - src.services.ollama_service - INFO - OllamaClient initialized
2025-03-15 12:00:16,125 - src.services.ollama_service - INFO - OllamaClient initialized
2025-03-15 12:01:29,735 - src.services.ollama_service - INFO - OllamaClient initialized
2025-03-15 12:01:31,391 - src.services.ollama_service - INFO - OllamaClient initialized
2025-03-15 12:01:43,121 - src.services.ollama_service - INFO - OllamaClient initialized
2025-03-15 12:01:44,765 - src.services.ollama_service - INFO - OllamaClient initialized
2025-03-15 12:01:58,075 - src.services.ollama_service - INFO - OllamaClient initialized
2025-03-15 12:01:59,469 - src.services.ollama_service - INFO - OllamaClient initialized
2025-03-15 12:02:11,512 - src.services.ollama_service - INFO - OllamaClient initialized
2025-03-15 12:02:11,781 - src.services.ollama_service - INFO - OllamaClient initialized
2025-03-15 12:02:15,143 - src.services.ollama_service - INFO - Generating manzai script for topic: カレーメシ
2025-03-15 12:02:15,147 - src.services.ollama_service - ERROR - HTTP Error: 404 Client Error: Not Found for url: http://localhost:11434/api/generate
Traceback (most recent call last):
  File "/home/persona/analysis/ManzAI_Studio/src/services/ollama_service.py", line 145, in generate_text_sync
    response.raise_for_status()
  File "/home/persona/.pyenv/versions/3.10.13/lib/python3.10/site-packages/requests/models.py", line 1024, in raise_for_status
    raise HTTPError(http_error_msg, response=self)
requests.exceptions.HTTPError: 404 Client Error: Not Found for url: http://localhost:11434/api/generate
2025-03-15 12:02:15,149 - src.services.ollama_service - WARNING - Failed to generate JSON response, falling back to text: Connection error: 404 Client Error: Not Found for url: http://localhost:11434/api/generate
2025-03-15 12:02:15,151 - src.services.ollama_service - ERROR - HTTP Error: 404 Client Error: Not Found for url: http://localhost:11434/api/generate
Traceback (most recent call last):
  File "/home/persona/analysis/ManzAI_Studio/src/services/ollama_service.py", line 145, in generate_text_sync
    response.raise_for_status()
  File "/home/persona/.pyenv/versions/3.10.13/lib/python3.10/site-packages/requests/models.py", line 1024, in raise_for_status
    raise HTTPError(http_error_msg, response=self)
requests.exceptions.HTTPError: 404 Client Error: Not Found for url: http://localhost:11434/api/generate

During handling of the above exception, another exception occurred:

Traceback (most recent call last):
  File "/home/persona/analysis/ManzAI_Studio/src/services/ollama_service.py", line 247, in generate_manzai_script
    generated_text = self.generate_text_sync(prompt, additional_options)
  File "/home/persona/analysis/ManzAI_Studio/src/services/ollama_service.py", line 158, in generate_text_sync
    raise OllamaServiceError(f"Connection error: {str(e)}")
src.services.ollama_service.OllamaServiceError: Connection error: 404 Client Error: Not Found for url: http://localhost:11434/api/generate

During handling of the above exception, another exception occurred:

Traceback (most recent call last):
  File "/home/persona/analysis/ManzAI_Studio/src/services/ollama_service.py", line 145, in generate_text_sync
    response.raise_for_status()
  File "/home/persona/.pyenv/versions/3.10.13/lib/python3.10/site-packages/requests/models.py", line 1024, in raise_for_status
    raise HTTPError(http_error_msg, response=self)
requests.exceptions.HTTPError: 404 Client Error: Not Found for url: http://localhost:11434/api/generate
2025-03-15 12:02:15,155 - src.services.ollama_service - ERROR - Failed to generate manzai script: Connection error: 404 Client Error: Not Found for url: http://localhost:11434/api/generate
2025-03-15 12:03:39,700 - src.services.ollama_service - INFO - OllamaClient initialized
2025-03-15 12:03:41,666 - src.services.ollama_service - INFO - OllamaClient initialized with base URL: http://localhost:11434
2025-03-15 12:04:33,424 - src.services.ollama_service - INFO - OllamaClient initialized with base URL: http://localhost:11434
2025-03-15 12:04:52,320 - src.services.ollama_service - INFO - OllamaClient initialized with base URL: http://localhost:11434
2025-03-15 12:04:52,320 - src.services.ollama_service - INFO - OllamaService initialized with model: yuma/DeepSeek-R1-Distill-Qwen-Japanese:14b
2025-03-15 12:04:57,471 - src.services.ollama_service - INFO - OllamaClient initialized with base URL: http://localhost:11434
2025-03-15 12:04:57,471 - src.services.ollama_service - INFO - OllamaService initialized with model: yuma/DeepSeek-R1-Distill-Qwen-Japanese:14b
2025-03-15 12:05:08,766 - src.services.ollama_service - INFO - OllamaClient initialized with base URL: http://localhost:11434
2025-03-15 12:05:08,766 - src.services.ollama_service - INFO - OllamaService initialized with model: yuma/DeepSeek-R1-Distill-Qwen-Japanese:14b
